<?xml version="1.0" encoding="utf-8"?>
<!-- =================================================================================== -->
<!-- |    This document was autogenerated by xacro from aslaug_simple_full.xacro       | -->
<!-- |    EDITING THIS FILE BY HAND IS NOT RECOMMENDED                                 | -->
<!-- =================================================================================== -->
<robot name="panda" xmlns:xacro="http://www.ros.org/wiki/xacro">
  <!-- <xacro:macro name="ridgeback_simple" params="hover_height:='0.5'"> -->
  <material name="dark_grey">
    <color rgba="0.2 0.2 0.2 1.0"/>
  </material>
  <material name="light_grey">
    <color rgba="0.4 0.4 0.4 1.0"/>
  </material>
  <material name="red">
    <color rgba="0.8 0.0 0.0 1.0"/>
  </material>
  <material name="white">
    <color rgba="0.9 0.9 0.9 1.0"/>
  </material>
  <material name="yellow">
    <color rgba="0.8 0.8 0.0 1.0"/>
  </material>
  <material name="black">
    <color rgba="0.15 0.15 0.15 1.0"/>
  </material>
  <gazebo>
    <plugin filename="libaslaug_simple_movement.so" name="aslaug_simple_movement">
      <commandTopic>cmd_vel</commandTopic>
      <odometryTopic>odom</odometryTopic>
      <odometryFrame>odom</odometryFrame>
      <odometryRate>20.0</odometryRate>
      <robotBaseFrame>base_footprint</robotBaseFrame>
    </plugin>
  </gazebo>
  <link name="base_link">
    <visual>
      <origin rpy="0 0 0" xyz="0 0 0"/>
      <geometry>
        <mesh filename="meshes/body.stl"/>
      </geometry>
      <material name="black"/>
    </visual>
    <visual>
      <origin rpy="0 0 3.141592" xyz="0 0 0"/>
      <geometry>
        <mesh filename="meshes/side-cover.stl"/>
      </geometry>
      <material name="yellow"/>
    </visual>
    <visual>
      <origin rpy="0 0 0" xyz="0 0 0"/>
      <geometry>
        <mesh filename="meshes/side-cover.stl"/>
      </geometry>
      <material name="yellow"/>
    </visual>
    <visual>
      <origin rpy="0 0 0" xyz="0 0 0"/>
      <geometry>
        <mesh filename="meshes/end-cover.stl"/>
      </geometry>
      <material name="black"/>
    </visual>
    <visual>
      <origin rpy="0 0 3.141592" xyz="0 0 0"/>
      <geometry>
        <mesh filename="meshes/end-cover.stl"/>
      </geometry>
      <material name="black"/>
    </visual>
    <visual>
      <origin rpy="0 0 0" xyz="0 0 0"/>
      <geometry>
        <mesh filename="meshes/lights.stl"/>
      </geometry>
      <material name="white"/>
    </visual>
    <visual>
      <origin rpy="0 0 3.141592" xyz="0 0 0"/>
      <geometry>
        <mesh filename="meshes/lights.stl"/>
      </geometry>
      <material name="red"/>
    </visual>
    <visual>
      <origin rpy="0 0 0" xyz="0 0 0"/>
      <geometry>
        <mesh filename="meshes/top.stl"/>
      </geometry>
      <material name="black"/>
    </visual>
    <collision>
      <origin xyz="0 0 0"/>
      <geometry>
        <mesh filename="meshes/body-collision.stl"/>
      </geometry>
    </collision>
    <collision>
      <origin rpy="0 0 0" xyz="0 0 0"/>
      <geometry>
        <mesh filename="meshes/top.stl"/>
      </geometry>
    </collision>
    <inertial>
      <origin rpy="1.570796 0 1.570796" xyz="0.012 0.002 0.067"/>
      <mass value="165.304"/>
      <inertia ixx="4.4744" ixy="0.03098" ixz="0.003647" iyy="7.1624" iyz="0.1228" izz="4.6155"/>
    </inertial>
  </link>
  <joint name="top_link_joint" type="fixed">
    <origin rpy="0 0 0" xyz="0 0 0.28"/>
    <parent link="base_link"/>
    <child link="top_link"/>
  </joint>
  <link name="top_link">

    </link>
  <!-- </xacro:macro> -->
  <!-- <xacro:include filename="$(find aslaug)/robots/panda/panda.transmission.xacro"/> -->
  <!-- end for simulation -->
  <!-- Chassis collision -->
  <gazebo reference="base_link">
    <sensor name="base_link_contact_sensor" type="contact">
      <update_rate>50.0</update_rate>
      <always_on>1</always_on>
      <contact>
        <collision>base_link_collision</collision>
        <collision>base_link_collision_1</collision>
        <collision>base_link_fixed_joint_lump__front_laser_collision_2</collision>
        <collision>base_link_fixed_joint_lump__panda_link0_collision_3</collision>
        <!-- <collision>base_link_fixed_joint_lump__chassis_link_collision</collision>
        <collision>base_link_fixed_joint_lump__front_laser_collision_1</collision>
        <collision>base_link_fixed_joint_lump__rear_laser_collision_2</collision>
        <collision>base_link_fixed_joint_lump__top_link_collision_2</collision>
        <collision>base_link_fixed_joint_lump__panda_link0_collision_2</collision> -->
        <topic>/collisions/chassis</topic>
      </contact>
      <plugin filename="libgazebo_ros_bumper.so" name="gazebo_ros_base_link_contact_plugin">
        <alwaysOn>true</alwaysOn>
        <updateRate>50.0</updateRate>
        <bumperTopicName>/collisions/chassis</bumperTopicName>
        <frameName>world</frameName>
      </plugin>
    </sensor>
  </gazebo>
  <!-- Panda link 1 collision -->
  <gazebo reference="panda_link1">
    <sensor name="panda_link1_contact_sensor" type="contact">
      <update_rate>50.0</update_rate>
      <always_on>1</always_on>
      <contact>
        <collision>panda_link1_collision</collision>
        <topic>/collisions/panda/arm</topic>
      </contact>
      <plugin filename="libgazebo_ros_bumper.so" name="gazebo_ros_panda_link1_contact_plugin">
        <alwaysOn>true</alwaysOn>
        <updateRate>50.0</updateRate>
        <bumperTopicName>/collisions/panda/arm</bumperTopicName>
        <frameName>world</frameName>
      </plugin>
    </sensor>
  </gazebo>
  <!-- Panda link 2 collision -->
  <gazebo reference="panda_link2">
    <sensor name="panda_link2_contact_sensor" type="contact">
      <update_rate>50.0</update_rate>
      <always_on>1</always_on>
      <contact>
        <collision>panda_link2_collision</collision>
        <topic>/collisions/panda/arm</topic>
      </contact>
      <plugin filename="libgazebo_ros_bumper.so" name="gazebo_ros_panda_link2_contact_plugin">
        <alwaysOn>true</alwaysOn>
        <updateRate>50.0</updateRate>
        <bumperTopicName>/collisions/panda/arm</bumperTopicName>
        <frameName>world</frameName>
      </plugin>
    </sensor>
  </gazebo>
  <!-- Panda link 3 collision -->
  <gazebo reference="panda_link3">
    <sensor name="panda_link3_contact_sensor" type="contact">
      <update_rate>50.0</update_rate>
      <always_on>1</always_on>
      <contact>
        <collision>panda_link3_collision</collision>
        <topic>/collisions/panda/arm</topic>
      </contact>
      <plugin filename="libgazebo_ros_bumper.so" name="gazebo_ros_panda_link3_contact_plugin">
        <alwaysOn>true</alwaysOn>
        <updateRate>50.0</updateRate>
        <bumperTopicName>/collisions/panda/arm</bumperTopicName>
        <frameName>world</frameName>
      </plugin>
    </sensor>
  </gazebo>
  <!-- Panda link 4 collision -->
  <gazebo reference="panda_link4">
    <sensor name="panda_link4_contact_sensor" type="contact">
      <update_rate>50.0</update_rate>
      <always_on>1</always_on>
      <contact>
        <collision>panda_link4_collision</collision>
        <topic>/collisions/panda/arm</topic>
      </contact>
      <plugin filename="libgazebo_ros_bumper.so" name="gazebo_ros_panda_link4_contact_plugin">
        <alwaysOn>true</alwaysOn>
        <updateRate>50.0</updateRate>
        <bumperTopicName>/collisions/panda/arm</bumperTopicName>
        <frameName>world</frameName>
      </plugin>
    </sensor>
  </gazebo>
  <!-- Panda link 5 collision -->
  <gazebo reference="panda_link5">
    <sensor name="panda_link5_contact_sensor" type="contact">
      <update_rate>50.0</update_rate>
      <always_on>1</always_on>
      <contact>
        <collision>panda_link5_collision</collision>
        <topic>/collisions/panda/arm</topic>
      </contact>
      <plugin filename="libgazebo_ros_bumper.so" name="gazebo_ros_panda_link5_contact_plugin">
        <alwaysOn>true</alwaysOn>
        <updateRate>50.0</updateRate>
        <bumperTopicName>/collisions/panda/arm</bumperTopicName>
        <frameName>world</frameName>
      </plugin>
    </sensor>
  </gazebo>
  <!-- Panda link 6 collision -->
  <gazebo reference="panda_link6">
    <sensor name="panda_link6_contact_sensor" type="contact">
      <update_rate>50.0</update_rate>
      <always_on>1</always_on>
      <contact>
        <collision>panda_link6_collision</collision>
        <topic>/collisions/panda/arm</topic>
      </contact>
      <plugin filename="libgazebo_ros_bumper.so" name="gazebo_ros_panda_link6_contact_plugin">
        <alwaysOn>true</alwaysOn>
        <updateRate>50.0</updateRate>
        <bumperTopicName>/collisions/panda/arm</bumperTopicName>
        <frameName>world</frameName>
      </plugin>
    </sensor>
  </gazebo>
  <!-- Panda link 7 collision -->
  <gazebo reference="panda_link7">
    <sensor name="panda_link7_contact_sensor" type="contact">
      <update_rate>50.0</update_rate>
      <always_on>1</always_on>
      <contact>
        <collision>panda_link7_collision</collision>
        <collision>panda_link7_fixed_joint_lump__panda_hand_collision_1</collision>
        <collision>panda_link7_fixed_joint_lump__kinect_kinect_link_collision_2</collision>
        <collision>panda_link7_fixed_joint_lump__kinect_kinect_ir_link_collision_3</collision>
        <collision>panda_link7_fixed_joint_lump__kinect_kinect_rgb_link_collision_4</collision>
        <topic>/collisions/panda/hand</topic>
      </contact>
      <plugin filename="libgazebo_ros_bumper.so" name="gazebo_ros_panda_link7_contact_plugin">
        <alwaysOn>true</alwaysOn>
        <updateRate>50.0</updateRate>
        <bumperTopicName>/collisions/panda/hand</bumperTopicName>
        <frameName>world</frameName>
      </plugin>
    </sensor>
  </gazebo>
  <!-- Panda link leftfinger collision -->
  <gazebo reference="panda_leftfinger">
    <sensor name="panda_leftfinger_contact_sensor" type="contact">
      <update_rate>50.0</update_rate>
      <always_on>1</always_on>
      <contact>
        <collision>panda_leftfinger_collision</collision>
        <topic>/collisions/panda/hand</topic>
      </contact>
      <plugin filename="libgazebo_ros_bumper.so" name="gazebo_ros_panda_leftfinger_contact_plugin">
        <alwaysOn>true</alwaysOn>
        <updateRate>50.0</updateRate>
        <bumperTopicName>/collisions/panda/hand</bumperTopicName>
        <frameName>world</frameName>
      </plugin>
    </sensor>
  </gazebo>
  <!-- Panda link rightfinger collision -->
  <gazebo reference="panda_rightfinger">
    <sensor name="panda_rightfinger_contact_sensor" type="contact">
      <update_rate>50.0</update_rate>
      <always_on>1</always_on>
      <contact>
        <collision>panda_rightfinger_collision</collision>
        <topic>/collisions/panda/hand</topic>
      </contact>
      <plugin filename="libgazebo_ros_bumper.so" name="gazebo_ros_panda_rightfinger_contact_plugin">
        <alwaysOn>true</alwaysOn>
        <updateRate>50.0</updateRate>
        <bumperTopicName>/collisions/panda/hand</bumperTopicName>
        <frameName>world</frameName>
      </plugin>
    </sensor>
  </gazebo>
  <joint name="front_laser_joint" type="fixed">
    <origin rpy="0 0 0.0" xyz="0.3932 0 0.2330"/>
    <parent link="base_link"/>
    <child link="front_laser"/>
  </joint>
  <link name="front_laser">
    <inertial>
      <mass value="0.130"/>
      <origin xyz="0 0 0"/>
      <inertia ixx="8.01666346e-05" ixy="0.0" ixz="0.0" iyy="8.01666346e-05" iyz="0.0" izz="5.4166645e-05"/>
    </inertial>
    <visual>
      <origin rpy="0 0 0" xyz="0 0 0"/>
      <geometry>
        <!-- Origin of this mesh is the focal point of the LIDAR. -->
        <mesh filename="meshes/ust-10lx.stl"/>
      </geometry>
      <material name="dark_grey"/>
    </visual>
    <collision>
      <origin rpy="0 0 0" xyz="0 0 -0.0122"/>
      <geometry>
        <box size="0.05 0.05 0.07"/>
      </geometry>
    </collision>
  </link>
  <gazebo reference="front_laser">
    <turnGravityOff>false</turnGravityOff>
    <sensor name="front_laser" type="ray">
      <pose>0 0 0 0 0 0</pose>
      <visualize>false</visualize>
      <update_rate>50</update_rate>
      <ray>
        <scan>
          <horizontal>
            <samples>720</samples>
            <resolution>1</resolution>
            <min_angle>-2.35619</min_angle>
            <max_angle>2.35619</max_angle>
          </horizontal>
        </scan>
        <range>
          <min>0.20</min>
          <max>10.0</max>
          <resolution>0.01</resolution>
        </range>
        <noise>
          <type>gaussian</type>
          <mean>0.0</mean>
          <stddev>0.001</stddev>
        </noise>
      </ray>
      <plugin filename="libgazebo_ros_laser.so" name="gazebo_ros_laser">
        <topicName>front/scan</topicName>
        <frameName>front_laser</frameName>
        <hokuyoMinIntensity>101</hokuyoMinIntensity>
      </plugin>
    </sensor>
    <material>Gazebo/DarkGrey</material>
  </gazebo>
  <gazebo>
    <plugin filename="libgazebo_ros_p3d.so" name="robot_groundtruth_sim">
      <alwaysOn>true</alwaysOn>
      <updateRate>100.0</updateRate>
      <bodyName>base_link</bodyName>
      <topicName>groundtruth</topicName>
      <gaussianNoise>0.0</gaussianNoise>
      <frameName>world</frameName>
      <xyzOffsets>0 0 0</xyzOffsets>
      <rpyOffsets>0 0 0</rpyOffsets>
    </plugin>
  </gazebo>
  <joint name="panda_joint_top_link" type="fixed">
    <parent link="top_link"/>
    <child link="panda_link0"/>
    <origin rpy="0 0 0" xyz="0.3 0 0"/>
  </joint>
  <!-- end for simulation -->
  <link name="panda_link0">
    <visual>
      <geometry>
        <mesh filename="meshes/visual/link0.dae"/>
      </geometry>
    </visual>
    <collision>
      <geometry>
        <mesh filename="meshes/collision/link0.stl"/>
      </geometry>
    </collision>
    <!-- for simulation -->
    <inertial>
      <origin rpy="0 0 0" xyz="0 0 0"/>
      <mass value="3.06"/>
      <inertia ixx="0.3" ixy="0.0" ixz="0.0" iyy="0.3" iyz="0.0" izz="0.3"/>
    </inertial>
    <!-- end for simulation -->
  </link>
  <link name="panda_link1">
    <visual>
      <geometry>
        <mesh filename="meshes/visual/link1.dae"/>
      </geometry>
    </visual>
    <collision>
      <geometry>
        <mesh filename="meshes/collision/link1.stl"/>
      </geometry>
    </collision>
    <!-- for simulation -->
    <inertial>
      <origin rpy="0 0 0" xyz="0 0 0"/>
      <mass value="2.34"/>
      <inertia ixx="0.3" ixy="0.0" ixz="0.0" iyy="0.3" iyz="0.0" izz="0.3"/>
    </inertial>
    <!-- end for simulation -->
  </link>
  <joint name="panda_joint1" type="revolute">
    <safety_controller k_position="100.0" k_velocity="40.0" soft_lower_limit="-2.8973" soft_upper_limit="2.8973"/>
    <origin rpy="0 0 0" xyz="0 0 0.333"/>
    <parent link="panda_link0"/>
    <child link="panda_link1"/>
    <axis xyz="0 0 1"/>
    <limit effort="8700" lower="-2.8973" upper="2.8973" velocity="2.1750"/>
    <!-- for simulation -->
    <dynamics damping="1.0"/>
    <!-- end for simulation -->
  </joint>
  <link name="panda_link2">
    <visual>
      <geometry>
        <mesh filename="meshes/visual/link2.dae"/>
      </geometry>
    </visual>
    <collision>
      <geometry>
        <mesh filename="meshes/collision/link2.stl"/>
      </geometry>
    </collision>
    <!-- for simulation -->
    <inertial>
      <origin rpy="0 0 0" xyz="0 0 0"/>
      <mass value="2.36"/>
      <inertia ixx="0.3" ixy="0.0" ixz="0.0" iyy="0.3" iyz="0.0" izz="0.3"/>
    </inertial>
    <!-- end for simulation -->
  </link>
  <joint name="panda_joint2" type="revolute">
    <safety_controller k_position="100.0" k_velocity="40.0" soft_lower_limit="-1.7628" soft_upper_limit="1.7628"/>
    <origin rpy="-1.57079632679 0 0" xyz="0 0 0"/>
    <parent link="panda_link1"/>
    <child link="panda_link2"/>
    <axis xyz="0 0 1"/>
    <limit effort="8700" lower="-1.7628" upper="1.7628" velocity="2.1750"/>
    <!-- for simulation -->
    <dynamics damping="1.0"/>
    <!-- end for simulation -->
  </joint>
  <link name="panda_link3">
    <visual>
      <geometry>
        <mesh filename="meshes/visual/link3.dae"/>
      </geometry>
    </visual>
    <collision>
      <geometry>
        <mesh filename="meshes/collision/link3.stl"/>
      </geometry>
    </collision>
    <!-- for simulation -->
    <inertial>
      <origin rpy="0 0 0" xyz="0 0 0"/>
      <mass value="2.38"/>
      <inertia ixx="0.3" ixy="0.0" ixz="0.0" iyy="0.3" iyz="0.0" izz="0.3"/>
    </inertial>
    <!-- end for simulation -->
  </link>
  <joint name="panda_joint3" type="revolute">
    <safety_controller k_position="100.0" k_velocity="40.0" soft_lower_limit="-2.8973" soft_upper_limit="2.8973"/>
    <origin rpy="1.57079632679 0 0" xyz="0 -0.316 0"/>
    <parent link="panda_link2"/>
    <child link="panda_link3"/>
    <axis xyz="0 0 1"/>
    <limit effort="8700" lower="-2.8973" upper="2.8973" velocity="2.1750"/>
    <!-- for simulation -->
    <dynamics damping="1.0"/>
    <!-- end for simulation -->
  </joint>
  <link name="panda_link4">
    <visual>
      <geometry>
        <mesh filename="meshes/visual/link4.dae"/>
      </geometry>
    </visual>
    <collision>
      <geometry>
        <mesh filename="meshes/collision/link4.stl"/>
      </geometry>
    </collision>
    <!-- for simulation -->
    <inertial>
      <origin rpy="0 0 0" xyz="0 0 0"/>
      <mass value="2.43"/>
      <inertia ixx="0.3" ixy="0.0" ixz="0.0" iyy="0.3" iyz="0.0" izz="0.3"/>
    </inertial>
    <!-- end for simulation -->
  </link>
  <joint name="panda_joint4" type="revolute">
    <safety_controller k_position="100.0" k_velocity="40.0" soft_lower_limit="-3.0718" soft_upper_limit="-0.0698"/>
    <origin rpy="1.57079632679 0 0" xyz="0.0825 0 0"/>
    <parent link="panda_link3"/>
    <child link="panda_link4"/>
    <axis xyz="0 0 1"/>
    <limit effort="8700" lower="-3.0718" upper="-0.0698" velocity="2.1750"/>
    <!-- for simulation -->
    <dynamics damping="1.0"/>
    <!-- end for simulation -->
  </joint>
  <link name="panda_link5">
    <visual>
      <geometry>
        <mesh filename="meshes/visual/link5.dae"/>
      </geometry>
    </visual>
    <collision>
      <geometry>
        <mesh filename="meshes/collision/link5.stl"/>
      </geometry>
    </collision>
    <!-- for simulation -->
    <inertial>
      <origin rpy="0 0 0" xyz="0 0 0"/>
      <mass value="3.5"/>
      <inertia ixx="0.3" ixy="0.0" ixz="0.0" iyy="0.3" iyz="0.0" izz="0.3"/>
    </inertial>
    <!-- end for simulation -->
  </link>
  <joint name="panda_joint5" type="revolute">
    <safety_controller k_position="100.0" k_velocity="40.0" soft_lower_limit="-2.8973" soft_upper_limit="2.8973"/>
    <origin rpy="-1.57079632679 0 0" xyz="-0.0825 0.384 0"/>
    <parent link="panda_link4"/>
    <child link="panda_link5"/>
    <axis xyz="0 0 1"/>
    <limit effort="1200" lower="-2.8973" upper="2.8973" velocity="2.6100"/>
    <!-- for simulation -->
    <dynamics damping="1.0"/>
    <!-- end for simulation -->
  </joint>
  <link name="panda_link6">
    <visual>
      <geometry>
        <mesh filename="meshes/visual/link6.dae"/>
      </geometry>
    </visual>
    <collision>
      <geometry>
        <mesh filename="meshes/collision/link6.stl"/>
      </geometry>
    </collision>
    <!-- for simulation -->
    <inertial>
      <origin rpy="0 0 0" xyz="0 0 0"/>
      <mass value="1.47"/>
      <inertia ixx="0.3" ixy="0.0" ixz="0.0" iyy="0.3" iyz="0.0" izz="0.3"/>
    </inertial>
    <!-- end for simulation -->
  </link>
  <joint name="panda_joint6" type="revolute">
    <safety_controller k_position="100.0" k_velocity="40.0" soft_lower_limit="-0.0175" soft_upper_limit="3.7525"/>
    <origin rpy="1.57079632679 0 0" xyz="0 0 0"/>
    <parent link="panda_link5"/>
    <child link="panda_link6"/>
    <axis xyz="0 0 1"/>
    <limit effort="120" lower="-0.0175" upper="3.7525" velocity="2.6100"/>
    <!-- for simulation -->
    <dynamics damping="1.0"/>
    <!-- end for simulation -->
  </joint>
  <link name="panda_link7">
    <visual>
      <geometry>
        <mesh filename="meshes/visual/link7.dae"/>
      </geometry>
    </visual>
    <collision>
      <geometry>
        <mesh filename="meshes/collision/link7.stl"/>
      </geometry>
    </collision>
    <!-- for simulation -->
    <inertial>
      <origin rpy="0 0 0" xyz="0 0 0"/>
      <mass value="0.45"/>
      <inertia ixx="0.3" ixy="0.0" ixz="0.0" iyy="0.3" iyz="0.0" izz="0.3"/>
    </inertial>
    <!-- end for simulation -->
  </link>
  <joint name="panda_joint7" type="revolute">
    <safety_controller k_position="100.0" k_velocity="40.0" soft_lower_limit="-2.8973" soft_upper_limit="2.8973"/>
    <origin rpy="1.57079632679 0 0" xyz="0.088 0 0"/>
    <parent link="panda_link6"/>
    <child link="panda_link7"/>
    <axis xyz="0 0 1"/>
    <limit effort="1200" lower="-2.8973" upper="2.8973" velocity="2.6100"/>
    <!-- for simulation -->
    <dynamics damping="1.0"/>
    <!-- end for simulation -->
  </joint>
  <link name="panda_link8">
    <!-- for simulation -->
    <inertial>
      <origin rpy="0 0 0" xyz="0 0 0"/>
      <mass value="0.0"/>
      <inertia ixx="0.3" ixy="0.0" ixz="0.0" iyy="0.3" iyz="0.0" izz="0.3"/>
    </inertial>
    <!-- end for simulation -->
  </link>
  <joint name="panda_joint8" type="fixed">
    <origin rpy="0 0 0" xyz="0 0 0.107"/>
    <parent link="panda_link7"/>
    <child link="panda_link8"/>
    <axis xyz="0 0 0"/>
  </joint>
  <joint name="panda_hand_joint" type="fixed">
    <parent link="panda_link8"/>
    <child link="panda_hand"/>
    <origin rpy="0 0 -0.785398163397" xyz="0 0 0"/>
  </joint>
  <link name="panda_hand">
    <visual>
      <geometry>
        <mesh filename="meshes/visual/hand.dae"/>
      </geometry>
    </visual>
    <collision>
      <geometry>
        <mesh filename="meshes/collision/hand.stl"/>
      </geometry>
    </collision>
    <!-- for simulation -->
    <inertial>
      <origin rpy="0 0 0" xyz="0 0 0"/>
      <mass value="0.68"/>
      <inertia ixx="0.1" ixy="0.0" ixz="0.0" iyy="0.1" iyz="0.0" izz="0.1"/>
    </inertial>
    <!-- end for simulation -->
  </link>
  <!-- Joints -->
  <joint name="kinect_kinect_joint" type="fixed">
    <origin rpy="0 -1.57079632679 3.14159265359" xyz="0.03 0 0"/>
    <parent link="panda_hand"/>
    <child link="kinect_kinect_link"/>
  </joint>
  <!-- kinect ir sensor physical attachment -->
  <joint name="kinect_kinect_ir_joint" type="fixed">
    <origin rpy="0.0 0.0 0.0" xyz="0.025 0.01 0.052"/>
    <parent link="kinect_kinect_link"/>
    <child link="kinect_kinect_ir_link"/>
  </joint>
  <!-- kinect ir sensor frame -->
  <joint name="kinect_kinect_ir_optical_frame_joint" type="fixed">
    <origin rpy="-1.570796 0.0 -1.570796" xyz="0 0 0"/>
    <parent link="kinect_kinect_ir_link"/>
    <child link="kinect_kinect_ir_optical_frame"/>
  </joint>
  <!-- kinect rgb sensor physical attachment -->
  <joint name="kinect_kinect_rgb_joint" type="fixed">
    <origin rpy="0.0 0.0 0.0" xyz="0.025 -0.015 0.052"/>
    <parent link="kinect_kinect_link"/>
    <child link="kinect_kinect_rgb_link"/>
  </joint>
  <!-- kinect rgb sensor frame -->
  <joint name="kinect_kinect_rgb_optical_frame_joint" type="fixed">
    <origin rpy="-1.570796 0.0 -1.570796" xyz="0 0 0"/>
    <parent link="kinect_kinect_rgb_link"/>
    <child link="kinect_kinect_rgb_optical_frame"/>
  </joint>
  <!-- Links -->
  <link name="kinect_kinect_link">
    <inertial>
      <mass value="0.1"/>
      <origin rpy="0.0 0.0 0.0" xyz="0.0 0.0 0.0"/>
      <inertia ixx="0.01" ixy="0.0" ixz="0.0" iyy="0.01" iyz="0.0" izz="0.01"/>
    </inertial>
    <visual>
      <origin rpy="0.0 0.0 0" xyz="0.0 0.0 0.0"/>
      <geometry>
        <mesh filename="meshes/kinect.dae" scale="1 1 1"/>
      </geometry>
      <material name="gray">
        <color rgba="0.5 0.5 0.5 1"/>
      </material>
    </visual>
    <collision>
      <origin rpy="0.0 0.0 0.0" xyz="0.0 0.0 0.0"/>
      <geometry>
        <mesh filename="meshes/kinect.dae" scale="1 1 1"/>
      </geometry>
    </collision>
  </link>
  <link name="kinect_kinect_ir_link">
    <inertial>
      <mass value="0.1"/>
      <origin rpy="0.0 0.0 0.0" xyz="0.0 0.0 0.0"/>
      <inertia ixx="0.01" ixy="0.0" ixz="0.0" iyy="0.01" iyz="0.0" izz="0.01"/>
    </inertial>
    <visual>
      <origin rpy="0.0 0.0 0.0" xyz="0.0 0.0 0.0"/>
      <geometry>
        <sphere radius="0.0005"/>
      </geometry>
    </visual>
    <collision>
      <origin rpy="0.0 0.0 0.0" xyz="0.0 0.0 0.0"/>
      <geometry>
        <sphere radius="0.0005"/>
      </geometry>
    </collision>
  </link>
  <link name="kinect_kinect_ir_optical_frame"/>
  <link name="kinect_kinect_rgb_link">
    <inertial>
      <mass value="0.1"/>
      <origin rpy="0.0 0.0 0.0" xyz="0.0 0.0 0.0"/>
      <inertia ixx="0.01" ixy="0.0" ixz="0.0" iyy="0.01" iyz="0.0" izz="0.01"/>
    </inertial>
    <visual>
      <origin rpy="0.0 0.0 0.0" xyz="0.0 0.0 0.0"/>
      <geometry>
        <sphere radius="0.0005"/>
      </geometry>
    </visual>
    <collision>
      <origin rpy="0.0 0.0 0.0" xyz="0.0 0.0 0.0"/>
      <geometry>
        <sphere radius="0.0005"/>
      </geometry>
    </collision>
  </link>
  <link name="kinect_kinect_rgb_optical_frame"/>
  <gazebo reference="kinect_kinect_ir_link">
    <sensor name="kinect_kinect_ir_link_rgb_sensor" type="depth">
      <always_on>true</always_on>
      <update_rate>30.0</update_rate>
      <camera>
        <horizontal_fov>1.04719733333</horizontal_fov>
        <image>
          <format>R8G8B8</format>
          <width>640</width>
          <height>480</height>
        </image>
        <clip>
          <near>0.01</near>
          <far>300.0</far>
        </clip>
        <noise>
          <type>gaussian</type>
          <!-- Noise is sampled independently per pixel on each frame.
						That pixel's noise value is added to each of its color
						channels, which at that point lie in the range [0,1]. -->
          <mean>0.0</mean>
          <stddev>0.007</stddev>
        </noise>
      </camera>
      <plugin filename="libgazebo_ros_openni_kinect.so" name="kinect_kinect_ir_link_controller">
        <alwaysOn>true</alwaysOn>
        <updateRate>0.0</updateRate>
        <cameraName>kinect_depth</cameraName>
        <imageTopicName>/kinect_depth/rgb/image_raw</imageTopicName>
        <cameraInfoTopicName>/kinect_depth/rgb/camera_info</cameraInfoTopicName>
        <depthImageTopicName>/kinect_depth/depth/image_raw</depthImageTopicName>
        <depthImageCameraInfoTopicName>/kinect_depth/depth/camera_info</depthImageCameraInfoTopicName>
        <pointCloudTopicName>/kinect_depth/depth_registered/points</pointCloudTopicName>
        <frameName>kinect_kinect_ir_optical_frame</frameName>
        <pointCloudCutoff>0.5</pointCloudCutoff>
        <distortionK1>0.00000001</distortionK1>
        <distortionK2>0.00000001</distortionK2>
        <distortionK3>0.00000001</distortionK3>
        <distortionT1>0.00000001</distortionT1>
        <distortionT2>0.00000001</distortionT2>
        <CxPrime>0</CxPrime>
        <Cx>0</Cx>
        <Cy>0</Cy>
        <focalLength>0</focalLength>
        <hackBaseline>0</hackBaseline>
      </plugin>
    </sensor>
    <material value="Gazebo/Red"/>
  </gazebo>
  <!-- Link0 -->
  <gazebo reference="panda_link0">
    <material>Gazebo/Grey</material>
    <mu1>0.2</mu1>
    <mu2>0.2</mu2>
    <gravity>0</gravity>
  </gazebo>
  <!-- Link1 -->
  <gazebo reference="panda_link1">
    <material>Gazebo/White</material>
    <mu1>0.2</mu1>
    <mu2>0.2</mu2>
    <gravity>0</gravity>
  </gazebo>
  <!-- Link2 -->
  <gazebo reference="panda_link2">
    <material>Gazebo/White</material>
    <mu1>0.2</mu1>
    <mu2>0.2</mu2>
    <gravity>0</gravity>
  </gazebo>
  <!-- Link3 -->
  <gazebo reference="panda_link3">
    <material>Gazebo/White</material>
    <mu1>0.2</mu1>
    <mu2>0.2</mu2>
    <gravity>0</gravity>
  </gazebo>
  <!-- Link4 -->
  <gazebo reference="panda_link4">
    <material>Gazebo/White</material>
    <mu1>0.2</mu1>
    <mu2>0.2</mu2>
    <gravity>0</gravity>
  </gazebo>
  <!-- Link5 -->
  <gazebo reference="panda_link5">
    <material>Gazebo/White</material>
    <mu1>0.2</mu1>
    <mu2>0.2</mu2>
    <gravity>0</gravity>
  </gazebo>
  <!-- Link6 -->
  <gazebo reference="panda_link6">
    <material>Gazebo/White</material>
    <mu1>0.2</mu1>
    <mu2>0.2</mu2>
    <gravity>0</gravity>
  </gazebo>
  <!-- Link7 -->
  <gazebo reference="panda_link7">
    <material>Gazebo/Grey</material>
    <mu1>0.2</mu1>
    <mu2>0.2</mu2>
    <gravity>0</gravity>
  </gazebo>
  <!-- Link8 -->
  <gazebo reference="panda_link8">
    <material>Gazebo/Grey</material>
    <mu1>0.2</mu1>
    <mu2>0.2</mu2>
    <gravity>0</gravity>
  </gazebo>
  <!-- LinkHand -->
  <gazebo reference="panda_hand">
    <material>Gazebo/Grey</material>
    <mu1>0.2</mu1>
    <mu2>0.2</mu2>
    <gravity>0</gravity>
  </gazebo>
  <!-- LinkRightFinger -->
  <gazebo reference="panda_rightfinger">
    <material>Gazebo/Grey</material>
    <mu1>0.2</mu1>
    <mu2>0.2</mu2>
    <gravity>0</gravity>
  </gazebo>
  <!-- LinkLeftFinger -->
  <gazebo reference="panda_leftfinger">
    <material>Gazebo/Grey</material>
    <mu1>0.2</mu1>
    <mu2>0.2</mu2>
    <gravity>0</gravity>
  </gazebo>
  <!-- <xacro:panda_transmission robot_name="$(arg robot_name)" load_hand="true" /> -->
  <!-- end for simulation -->
  <!-- Turn off gravity for panda -->
  <!-- <xacro:include filename="$(find aslaug)/robots/accessoires/turn_off_gravity.gazebo.xacro"/> -->
  <gazebo>
    <plugin filename="libgazebo_ros_joint_state_publisher.so" name="gazbo_ros_joint_state_panda_link1">
      <jointName>panda_joint1</jointName>
      <robotNamespace>/</robotNamespace>
      <updateRate>50.0</updateRate>
    </plugin>
    <plugin filename="libgazebo_ros_joint_state_publisher.so" name="gazbo_ros_joint_state_panda_link2">
      <jointName>panda_joint2</jointName>
      <robotNamespace>/</robotNamespace>
      <updateRate>50.0</updateRate>
    </plugin>
    <plugin filename="libgazebo_ros_joint_state_publisher.so" name="gazbo_ros_joint_state_panda_link3">
      <jointName>panda_joint3</jointName>
      <robotNamespace>/</robotNamespace>
      <updateRate>50.0</updateRate>
    </plugin>
    <plugin filename="libgazebo_ros_joint_state_publisher.so" name="gazbo_ros_joint_state_panda_link4">
      <jointName>panda_joint4</jointName>
      <robotNamespace>/</robotNamespace>
      <updateRate>50.0</updateRate>
    </plugin>
    <plugin filename="libgazebo_ros_joint_state_publisher.so" name="gazbo_ros_joint_state_panda_link5">
      <jointName>panda_joint5</jointName>
      <robotNamespace>/</robotNamespace>
      <updateRate>50.0</updateRate>
    </plugin>
    <plugin filename="libgazebo_ros_joint_state_publisher.so" name="gazbo_ros_joint_state_panda_link6">
      <jointName>panda_joint6</jointName>
      <robotNamespace>/</robotNamespace>
      <updateRate>50.0</updateRate>
    </plugin>
    <plugin filename="libgazebo_ros_joint_state_publisher.so" name="gazbo_ros_joint_state_panda_link7">
      <jointName>panda_joint7</jointName>
      <robotNamespace>/</robotNamespace>
      <updateRate>50.0</updateRate>
    </plugin>
  </gazebo>
</robot>
